package lesson_48;

public class Main1 {
    /*
    Exceptions ( исключения)

    Ошибки наследуют класс Throwable и делятся на ошибки, возникающие в джава-машине( вне
    нашего контроля) и исключения ( то, что можно обрабатывать в программе)
     */
    public static void main(String[] args) {
        int num1, num2;


        try{
            num1 = 1;
            num2 = 4;
            int divide = num2 / num1;
            //    System.out.println("num2/num1 = " + divide);
            //    System.out.println("End of try block");
        }
        catch (ArithmeticException e){
            System.out.println("Do not divide by zero !");
            System.out.println(e.getMessage());
        }


        // System.out.println("After exception occured");

        /*
        Типы исключений
        Исключения бывают "Встроенные"  и написанные пользователем

        Встроенные исключения делятся на две категории:
        Checked( проверяемые) и Unchecked Exceptions ( непроверяемые исключения)

        Важные определения при работе с исключениями :
        1. try -  код, который может вызвать появление исключения помещается внутрь блока try.
            Блок try  определяет произошло ли исключение и если да, то передает управление программой соотвествующему
            блоку catch или блоку finally

        2. catch - это блок, в котором содержится код для обработки возникшего исключения. Блок catch  выполняется только
            в том случае если произошло исключение и существует в связке с блоком try.

        3. finally - этот блок будет выполняться всегда независимо от того, произошло исключение или нет.

        4. throw - используется для того, чтобы бросить исключение

        5. throws - используется в сигнатуре метода и указывает на то, что метод может бросить исключение


        TRY-CATCH  блок
        try{
         блок кода
        } catch( Exception e){
          код для обработки исключения
        }

        Одному блоку try  может соответствовать несколько блоков catch,  каждый из которых отвечает за обработку своего
        вида исключений.
        Можно также создать  блок catch,  который будет отлавливать все исключения. В этом случае он должен
        ловить Exception e  и стоять последним после всех остальных блоков catch,  ловящих отдельные исключения и относящиеся
        к одному и тому же блоку try

         */

        int[] ints ={1,2,4};

        try{
            //    String nullString = null;
            //    nullString.length();
            num1 = ints[1];
            num2 = ints[2];
            int divide = num2 / num1;
            //    System.out.println(ints[34]);
            //    System.out.println("num2/num1 = " + divide);
            //    System.out.println("End of try block");
        }

        catch (ArithmeticException e){
            System.out.println("Do not divide by zero !");
            System.out.println(e.getMessage());
        }
        catch (ArrayIndexOutOfBoundsException e){
            System.out.println(e.getMessage());
        }
        catch (Exception e){
            System.out.println("Exception occured");
            System.out.println(e.getMessage());
        }


        //  System.out.println("After exception occured");



        int[] numbers = {4,8,16,32,64,128,256,512};
        int[] dividers = {2,0,4,8,0,8};


        for( int i = 0; i < numbers.length; i++){
            try {
                System.out.println(numbers[i] + "/" + dividers[i] + " = " + numbers[i] / dividers[i]);
            }
            catch (ArithmeticException exception){
                System.out.println("Can't divide by zero!");
            }
            catch (ArrayIndexOutOfBoundsException exception){
                System.out.println("Dividers array is finished and no matching element was not found");
            }

        }

        /*
             блок finally


             try{
               блок кода
               }
             catch{
             обработка  исключения
             }
             finally {
              код, который должен выполниться в любом случае}


             */
        System.out.println("----------finally------------------");
        try{
            int a = 100/2;
            System.out.println(a);
        }
        catch (ArithmeticException e){
            System.out.println(e.getMessage());
        }

        finally {
            System.out.println("This is finally block");
        }

        System.out.println("we are out of the try-catch-finally");


        /*
        1. finally  не существует без блока try
        2. finally  не является обязательным
        3. если исключения не происходит, то finally  выполняется вслед за блоком try,  если происходит то после
            catch
        4. Код в finally  выполняется даже если в блоке try  содержатся команды return, break, continue
        5.  блоки try -  finally  могут существовать без блока catch
         */


        //   System.out.println(example());
        for(int i=0; i < 3; i++){
            //      example1(i);
            System.out.println();
        }

        checkCandidates(19,20);
    }
    public static int example(){
        try {
            return 1;
        }
        finally {
            System.out.println("Finally runs even when return is present" );
        }
    }

    public static void example1(int num){
        int t;
        int[] ints = new int[2];

        System.out.println("received " +num);
        try {
            switch (num) {
                case 0:
                    t = 20 / num; // деление на ноль
                    break;
                case 1:
                    ints[10] = 100; // неправильный индекс
                    break;
                case 2:
                    return;  //  возврат из блока try
            }
        }
        catch (ArithmeticException e){
            System.out.println("Do not divide by zero!");
            return;
        }
        catch (ArrayIndexOutOfBoundsException e){
            System.out.println("No such index is found");
        }
        finally{
            System.out.println("Finally always executes");

        }
    }

    /*
    throw -  бросать исключение
    throw new exception_class( " message")
     */
    public static void checkCandidates( int age, int weight){

        if( age < 10 && weight < 40 ){
            throw new ArithmeticException("Sorry, you are not good for our section");
        }
        else{
            System.out.println("Welcome aboard!");
        }
    }
}
